<?xml version="1.0"?>
<robot name="vision_voyager" xmlns:xacro="http://www.ros.org/wiki/xacro">

  <xacro:property name="chassis_l" value="0.17"/>
  <xacro:property name="chassis_w" value="0.10"/>
  <xacro:property name="chassis_h" value="0.04"/>
  <xacro:property name="wheel_r" value="0.033"/>
  <xacro:property name="wheel_w" value="0.025"/>

  <material name="blue"> <color rgba="0 0 0.8 1"/> </material>
  <material name="black"> <color rgba="0 0 0 1"/> </material>

  <link name="base_footprint"/>
  <joint name="base_joint" type="fixed">
    <parent link="base_footprint"/>
    <child link="base_link"/>
    <origin xyz="0 0 ${wheel_r}" rpy="0 0 0"/>
  </joint>

  <link name="base_link">
    <visual>
      <origin xyz="0 0 0.02" rpy="0 0 0"/>
      <geometry> <box size="${chassis_l} ${chassis_w} ${chassis_h}"/> </geometry>
      <material name="blue"/>
    </visual>
    <collision>
      <origin xyz="0 0 0.02" rpy="0 0 0"/>
      <geometry> <box size="${chassis_l} ${chassis_w} ${chassis_h}"/> </geometry>
    </collision>
    <inertial>
      <origin xyz="0 0 0.02" rpy="0 0 0"/>
      <mass value="0.5"/>
      <inertia ixx="0.001" ixy="0" ixz="0" iyy="0.001" iyz="0" izz="0.001"/>
    </inertial>
  </link>

  <xacro:macro name="wheel" params="prefix x y">
    <link name="${prefix}_wheel">
      <visual>
        <origin rpy="${pi/2} 0 0" xyz="0 0 0"/>
        <geometry> <cylinder radius="${wheel_r}" length="${wheel_w}"/> </geometry>
        <material name="black"/>
      </visual>
      <collision>
        <origin rpy="${pi/2} 0 0" xyz="0 0 0"/>
        <geometry> <cylinder radius="${wheel_r}" length="${wheel_w}"/> </geometry>
      </collision>
      <inertial>
        <mass value="0.1"/>
        <inertia ixx="1e-4" ixy="0" ixz="0" iyy="1e-4" iyz="0" izz="1e-4"/>
      </inertial>
    </link>
    <joint name="${prefix}_wheel_joint" type="continuous">
      <parent link="base_link"/>
      <child link="${prefix}_wheel"/>
      <origin xyz="${x} ${y} 0" rpy="0 0 0"/>
      <axis xyz="0 1 0"/>
    </joint>
  </xacro:macro>

  <xacro:wheel prefix="front_left"  x="0.06"  y="0.06"/>
  <xacro:wheel prefix="front_right" x="0.06"  y="-0.06"/>
  <xacro:wheel prefix="rear_left"   x="-0.06" y="0.06"/>
  <xacro:wheel prefix="rear_right"  x="-0.06" y="-0.06"/>

  <gazebo>
    <plugin name="skid_steer_drive" filename="libgazebo_ros_diff_drive.so">
      <ros>
        <remapping>cmd_vel:=cmd_vel</remapping>
        <remapping>odom:=odom</remapping>
      </ros>
      <update_rate>30</update_rate>

      <num_wheel_pairs>2</num_wheel_pairs>
      <left_joint>front_left_wheel_joint</left_joint>
      <left_joint>rear_left_wheel_joint</left_joint>
      <right_joint>front_right_wheel_joint</right_joint>
      <right_joint>rear_right_wheel_joint</right_joint>

      <wheel_separation>0.12</wheel_separation>
      <wheel_diameter>0.066</wheel_diameter>

      <max_wheel_torque>20</max_wheel_torque>
      <max_wheel_acceleration>1.0</max_wheel_acceleration>

      <publish_odom>true</publish_odom>
      <publish_odom_tf>true</publish_odom_tf>
      <odometry_frame>odom</odometry_frame>
      <robot_base_frame>base_footprint</robot_base_frame>
    </plugin>
  </gazebo>

  <gazebo reference="base_link"><material>Gazebo/Blue</material></gazebo>
  <gazebo reference="front_left_wheel"><material>Gazebo/Black</material></gazebo>
  <gazebo reference="front_right_wheel"><material>Gazebo/Black</material></gazebo>
  <gazebo reference="rear_left_wheel"><material>Gazebo/Black</material></gazebo>
  <gazebo reference="rear_right_wheel"><material>Gazebo/Black</material></gazebo>

</robot>